Traceback (most recent call last):
  File "/Library/Frameworks/Python.framework/Versions/3.9/lib/python3.9/site-packages/jupyter_cache/executors/utils.py", line 51, in single_nb_execution
    executenb(
  File "/Library/Frameworks/Python.framework/Versions/3.9/lib/python3.9/site-packages/nbclient/client.py", line 1087, in execute
    return NotebookClient(nb=nb, resources=resources, km=km, **kwargs).execute()
  File "/Library/Frameworks/Python.framework/Versions/3.9/lib/python3.9/site-packages/nbclient/util.py", line 74, in wrapped
    return just_run(coro(*args, **kwargs))
  File "/Library/Frameworks/Python.framework/Versions/3.9/lib/python3.9/site-packages/nbclient/util.py", line 53, in just_run
    return loop.run_until_complete(coro)
  File "/Library/Frameworks/Python.framework/Versions/3.9/lib/python3.9/asyncio/base_events.py", line 642, in run_until_complete
    return future.result()
  File "/Library/Frameworks/Python.framework/Versions/3.9/lib/python3.9/site-packages/nbclient/client.py", line 540, in async_execute
    await self.async_execute_cell(
  File "/Library/Frameworks/Python.framework/Versions/3.9/lib/python3.9/site-packages/nbclient/client.py", line 832, in async_execute_cell
    self._check_raise_for_error(cell, exec_reply)
  File "/Library/Frameworks/Python.framework/Versions/3.9/lib/python3.9/site-packages/nbclient/client.py", line 740, in _check_raise_for_error
    raise CellExecutionError.from_cell_and_msg(cell, exec_reply['content'])
nbclient.exceptions.CellExecutionError: An error occurred while executing the following cell:
------------------
%load hello.py
------------------

[0;31m---------------------------------------------------------------------------[0m
[0;31mNameError[0m                                 Traceback (most recent call last)
[0;32m/Library/Frameworks/Python.framework/Versions/3.9/lib/python3.9/site-packages/IPython/core/interactiveshell.py[0m in [0;36mfind_user_code[0;34m(self, target, raw, py_only, skip_encoding_cookie, search_ns)[0m
[1;32m   3736[0m         [0;32mtry[0m[0;34m:[0m                                              [0;31m# User namespace[0m[0;34m[0m[0;34m[0m[0m
[0;32m-> 3737[0;31m             [0mcodeobj[0m [0;34m=[0m [0meval[0m[0;34m([0m[0mtarget[0m[0;34m,[0m [0mself[0m[0;34m.[0m[0muser_ns[0m[0;34m)[0m[0;34m[0m[0;34m[0m[0m
[0m[1;32m   3738[0m         [0;32mexcept[0m [0mException[0m[0;34m:[0m[0;34m[0m[0;34m[0m[0m

[0;32m<string>[0m in [0;36m<module>[0;34m[0m

[0;31mNameError[0m: name 'hello' is not defined

During handling of the above exception, another exception occurred:

[0;31mValueError[0m                                Traceback (most recent call last)
[0;32m<ipython-input-6-78ca1d793f42>[0m in [0;36m<module>[0;34m[0m
[0;32m----> 1[0;31m [0mget_ipython[0m[0;34m([0m[0;34m)[0m[0;34m.[0m[0mrun_line_magic[0m[0;34m([0m[0;34m'load'[0m[0;34m,[0m [0;34m'hello.py'[0m[0;34m)[0m[0;34m[0m[0;34m[0m[0m
[0m
[0;32m/Library/Frameworks/Python.framework/Versions/3.9/lib/python3.9/site-packages/IPython/core/interactiveshell.py[0m in [0;36mrun_line_magic[0;34m(self, magic_name, line, _stack_depth)[0m
[1;32m   2325[0m                 [0mkwargs[0m[0;34m[[0m[0;34m'local_ns'[0m[0;34m][0m [0;34m=[0m [0mself[0m[0;34m.[0m[0mget_local_scope[0m[0;34m([0m[0mstack_depth[0m[0;34m)[0m[0;34m[0m[0;34m[0m[0m
[1;32m   2326[0m             [0;32mwith[0m [0mself[0m[0;34m.[0m[0mbuiltin_trap[0m[0;34m:[0m[0;34m[0m[0;34m[0m[0m
[0;32m-> 2327[0;31m                 [0mresult[0m [0;34m=[0m [0mfn[0m[0;34m([0m[0;34m*[0m[0margs[0m[0;34m,[0m [0;34m**[0m[0mkwargs[0m[0;34m)[0m[0;34m[0m[0;34m[0m[0m
[0m[1;32m   2328[0m             [0;32mreturn[0m [0mresult[0m[0;34m[0m[0;34m[0m[0m
[1;32m   2329[0m [0;34m[0m[0m

[0;32m<decorator-gen-39>[0m in [0;36mload[0;34m(self, arg_s)[0m

[0;32m/Library/Frameworks/Python.framework/Versions/3.9/lib/python3.9/site-packages/IPython/core/magic.py[0m in [0;36m<lambda>[0;34m(f, *a, **k)[0m
[1;32m    185[0m     [0;31m# but it's overkill for just that one bit of state.[0m[0;34m[0m[0;34m[0m[0;34m[0m[0m
[1;32m    186[0m     [0;32mdef[0m [0mmagic_deco[0m[0;34m([0m[0marg[0m[0;34m)[0m[0;34m:[0m[0;34m[0m[0;34m[0m[0m
[0;32m--> 187[0;31m         [0mcall[0m [0;34m=[0m [0;32mlambda[0m [0mf[0m[0;34m,[0m [0;34m*[0m[0ma[0m[0;34m,[0m [0;34m**[0m[0mk[0m[0;34m:[0m [0mf[0m[0;34m([0m[0;34m*[0m[0ma[0m[0;34m,[0m [0;34m**[0m[0mk[0m[0;34m)[0m[0;34m[0m[0;34m[0m[0m
[0m[1;32m    188[0m [0;34m[0m[0m
[1;32m    189[0m         [0;32mif[0m [0mcallable[0m[0;34m([0m[0marg[0m[0;34m)[0m[0;34m:[0m[0;34m[0m[0;34m[0m[0m

[0;32m/Library/Frameworks/Python.framework/Versions/3.9/lib/python3.9/site-packages/IPython/core/magics/code.py[0m in [0;36mload[0;34m(self, arg_s)[0m
[1;32m    331[0m         [0msearch_ns[0m [0;34m=[0m [0;34m'n'[0m [0;32min[0m [0mopts[0m[0;34m[0m[0;34m[0m[0m
[1;32m    332[0m [0;34m[0m[0m
[0;32m--> 333[0;31m         [0mcontents[0m [0;34m=[0m [0mself[0m[0;34m.[0m[0mshell[0m[0;34m.[0m[0mfind_user_code[0m[0;34m([0m[0margs[0m[0;34m,[0m [0msearch_ns[0m[0;34m=[0m[0msearch_ns[0m[0;34m)[0m[0;34m[0m[0;34m[0m[0m
[0m[1;32m    334[0m [0;34m[0m[0m
[1;32m    335[0m         [0;32mif[0m [0;34m's'[0m [0;32min[0m [0mopts[0m[0;34m:[0m[0;34m[0m[0;34m[0m[0m

[0;32m/Library/Frameworks/Python.framework/Versions/3.9/lib/python3.9/site-packages/IPython/core/interactiveshell.py[0m in [0;36mfind_user_code[0;34m(self, target, raw, py_only, skip_encoding_cookie, search_ns)[0m
[1;32m   3737[0m             [0mcodeobj[0m [0;34m=[0m [0meval[0m[0;34m([0m[0mtarget[0m[0;34m,[0m [0mself[0m[0;34m.[0m[0muser_ns[0m[0;34m)[0m[0;34m[0m[0;34m[0m[0m
[1;32m   3738[0m         [0;32mexcept[0m [0mException[0m[0;34m:[0m[0;34m[0m[0;34m[0m[0m
[0;32m-> 3739[0;31m             raise ValueError(("'%s' was not found in history, as a file, url, "
[0m[1;32m   3740[0m                                 "nor in the user namespace.") % target)
[1;32m   3741[0m [0;34m[0m[0m

[0;31mValueError[0m: 'hello.py' was not found in history, as a file, url, nor in the user namespace.
ValueError: 'hello.py' was not found in history, as a file, url, nor in the user namespace.

